<robot name="simplified_gripper">
  <!-- Base Link -->
  <link name="base">
    <inertial>
      <origin rpy="0 0 0" xyz="0 0 0"/>
      <mass value="1.0"/>
      <inertia ixx="1.0" ixy="0" ixz="0" iyy="1.0" iyz="0" izz="1.0"/>
    </inertial>
  </link>

  <!-- Panda Hand Link -->
  <link name="panda_hand">
    <inertial>
      <origin rpy="0 0 0" xyz="0 0 0.04"/>
      <mass value="0.81"/>
      <inertia ixx="0.1" ixy="0" ixz="0" iyy="0.1" iyz="0" izz="0.1"/>
    </inertial>
    <visual>
      <geometry>
        <box size="0.05 0.05 0.05"/>
      </geometry>
      <material name="panda_white"/>
    </visual>
  </link>

  <!-- Left Finger Link -->
  <link name="panda_leftfinger">
    <inertial>
      <origin rpy="0 0 0" xyz="0 0.01 0.02"/>
      <mass value="0.1"/>
      <inertia ixx="0.1" ixy="0" ixz="0" iyy="0.1" iyz="0" izz="0.1"/>
    </inertial>
    <visual>
      <geometry>
        <box size="0.01 0.02 0.02"/>
      </geometry>
    </visual>
  </link>

  <!-- Right Finger Link -->
  <link name="panda_rightfinger">
    <inertial>
      <origin rpy="0 0 0" xyz="0 -0.01 0.02"/>
      <mass value="0.1"/>
      <inertia ixx="0.1" ixy="0" ixz="0" iyy="0.1" iyz="0" izz="0.1"/>
    </inertial>
    <visual>
      <geometry>
        <box size="0.01 0.02 0.02"/>
      </geometry>
    </visual>
  </link>

  <!-- Fixed Joint: Base to Panda Hand -->
  <joint name="fixed_base_to_hand" type="fixed">
    <parent link="base"/>
    <child link="panda_hand"/>


  <joint name="panda_finger_joint1" type="prismatic">
    <parent link="panda_hand"/>
    <child link="panda_leftfinger"/>
    <origin rpy="0 0 0" xyz="0 0 0.0584"/>
    <axis xyz="0 1 0"/>
    <limit effort="20" lower="0.0" upper="0.04" velocity="0.2"/>
  </joint>


 <joint name="panda_finger_joint2" type="prismatic">
    <parent link="panda_hand"/>
    <child link="panda_rightfinger"/>
    <origin rpy="0 0 0" xyz="0 0 0.0584"/>
    <axis xyz="0 -1 0"/>
    <limit effort="20" lower="0.0" upper="0.04" velocity="0.2"/>
 </joint>

</robot>
